<?xml version="1.0" encoding="utf-8"?>
<robot name="arm_description">
  <link name="world" />
  <joint name="world_to_base" type="fixed">
    <parent link="world" />
    <child link="base_link" />
    <origin xyz="0 0 0" rpy="0 0 0" />
  </joint>
  <link
    name="base_link">
    <inertial>
      <origin
        xyz="-7.33667051250331E-07 -0.000806795620128295 0.000435035650231941"
        rpy="0 0 0" />
      <mass
        value="6.52720522593112" />
      <inertia
        ixx="1.57111264401313"
        ixy="3.5412325745297E-08"
        ixz="3.43473341339994E-09"
        iyy="1.57098803430044"
        iyz="-1.30977759884657E-05"
        izz="3.14201095739205" />
    </inertial>
    <visual>
      <origin
        xyz="0 0 0"
        rpy="0 0 0" />
      <geometry>
        <mesh
          filename="package://arm_description/meshes/base_link.STL" />
      </geometry>
      <material
        name="">
        <color
          rgba="0.752941176470588 0.752941176470588 0.752941176470588 1" />
      </material>
    </visual>
    <collision>
      <origin
        xyz="0 0 0"
        rpy="0 0 0" />
      <geometry>
        <mesh
          filename="package://arm_description/meshes/base_link.STL" />
      </geometry>
    </collision>
  </link>
  <link
    name="link_1">
    <inertial>
      <origin
        xyz="0.00362239334791756 -3.81795642908495E-05 0.140982620125569"
        rpy="0 0 0" />
      <mass
        value="0.141639977131661" />
      <inertia
        ixx="8.98141382308835E-05"
        ixy="1.13468736177936E-08"
        ixz="3.51673525250542E-06"
        iyy="9.15722320805618E-05"
        iyz="3.65425922924879E-08"
        izz="0.000140053948831358" />
    </inertial>
    <visual>
      <origin
        xyz="0 0 0"
        rpy="0 0 0" />
      <geometry>
        <mesh
          filename="package://arm_description/meshes/link_1.STL" />
      </geometry>
      <material
        name="">
        <color
          rgba="0.752941176470588 0.752941176470588 0.752941176470588 1" />
      </material>
    </visual>
    <collision>
      <origin
        xyz="0 0 0"
        rpy="0 0 0" />
      <geometry>
        <mesh
          filename="package://arm_description/meshes/link_1.STL" />
      </geometry>
    </collision>
  </link>
  <joint
    name="joint_1"
    type="revolute">
    <origin
      xyz="0 0 0"
      rpy="0 0 0" />
    <parent
      link="base_link" />
    <child
      link="link_1" />
    <axis
      xyz="0 0 1" />
    <limit
      lower="-1.57"
      upper="3.14"
      effort="200"
      velocity="10" />
  </joint>
  <link
    name="link_2">
    <inertial>
      <origin
        xyz="7.53940182483814E-06 0.00505678180282543 0.0842129380713662"
        rpy="0 0 0" />
      <mass
        value="0.143507549223786" />
      <inertia
        ixx="9.77478537604331E-05"
        ixy="-1.67427633619266E-08"
        ixz="-1.80834387568079E-08"
        iyy="9.07459548934156E-05"
        iyz="3.57849204977034E-06"
        izz="0.000147113534917112" />
    </inertial>
    <visual>
      <origin
        xyz="0 0 0"
        rpy="0 0 0" />
      <geometry>
        <mesh
          filename="package://arm_description/meshes/link_2.STL" />
      </geometry>
      <material
        name="">
        <color
          rgba="0.752941176470588 0.752941176470588 0.752941176470588 1" />
      </material>
    </visual>
    <collision>
      <origin
        xyz="0 0 0"
        rpy="0 0 0" />
      <geometry>
        <mesh
          filename="package://arm_description/meshes/link_2.STL" />
      </geometry>
    </collision>
  </link>
  <joint
    name="joint_2"
    type="revolute">
    <origin
      xyz="0 0 0.1464"
      rpy="1.5707963267949 0 1.5707963267949" />
    <parent
      link="link_1" />
    <child
      link="link_2" />
    <axis
      xyz="0 0 1" />
    <limit
      lower="-1.57"
      upper="1.57"
      effort="200"
      velocity="10" />
  </joint>
  <link
    name="link_3">
    <inertial>
      <origin
        xyz="-0.003307750182467 -1.51931359661239E-05 -0.215292675404989"
        rpy="0 0 0" />
      <mass
        value="0.173954075434222" />
      <inertia
        ixx="0.000144630940442922"
        ixy="-1.32847181188018E-07"
        ixz="3.53526021477459E-06"
        iyy="0.000147338139082199"
        iyz="-6.41277682296157E-09"
        izz="0.000161646518516295" />
    </inertial>
    <visual>
      <origin
        xyz="0 0 0"
        rpy="0 0 0" />
      <geometry>
        <mesh
          filename="package://arm_description/meshes/link_3.STL" />
      </geometry>
      <material
        name="">
        <color
          rgba="0.752941176470588 0.752941176470588 0.752941176470588 1" />
      </material>
    </visual>
    <collision>
      <origin
        xyz="0 0 0"
        rpy="0 0 0" />
      <geometry>
        <mesh
          filename="package://arm_description/meshes/link_3.STL" />
      </geometry>
    </collision>
  </link>
  <joint
    name="joint_3"
    type="revolute">
    <origin
      xyz="0 0 0.0894999999999936"
      rpy="1.5707963267949 -1.5707963267949 0" />
    <parent
      link="link_2" />
    <child
      link="link_3" />
    <axis
      xyz="0 0 -1" />
    <limit
      lower="-3.14"
      upper="3.14"
      effort="200"
      velocity="10" />
  </joint>
  <link
    name="link_4">
    <inertial>
      <origin
        xyz="-3.69732387454497E-05 -0.00339659287195776 0.0858843482112302"
        rpy="0 0 0" />
      <mass
        value="0.148325167434625" />
      <inertia
        ixx="9.83824919124808E-05"
        ixy="-8.95348942307497E-09"
        ixz="3.53186062441247E-08"
        iyy="9.2436601034005E-05"
        iyz="-3.58230406317328E-06"
        izz="0.000148216123686448" />
    </inertial>
    <visual>
      <origin
        xyz="0 0 0"
        rpy="0 0 0" />
      <geometry>
        <mesh
          filename="package://arm_description/meshes/link_4.STL" />
      </geometry>
      <material
        name="">
        <color
          rgba="0.752941176470588 0.752941176470588 0.752941176470588 1" />
      </material>
    </visual>
    <collision>
      <origin
        xyz="0 0 0"
        rpy="0 0 0" />
      <geometry>
        <mesh
          filename="package://arm_description/meshes/link_4.STL" />
      </geometry>
    </collision>
  </link>
  <joint
    name="joint_4"
    type="revolute">
    <origin
      xyz="0 0 -0.24698520586243"
      rpy="1.5707963267949 0 -1.5707963267949" />
    <parent
      link="link_3" />
    <child
      link="link_4" />
    <axis
      xyz="0 0 1" />
    <limit
      lower="-2.09"
      upper="2.09"
      effort="200"
      velocity="10" />
  </joint>
  <link
    name="link_5">
    <inertial>
      <origin
        xyz="0.00206792792814745 -2.76614863313901E-05 0.175346578298025"
        rpy="0 0 0" />
      <mass
        value="0.170949127914978" />
      <inertia
        ixx="0.000112877897565311"
        ixy="1.33876282485743E-07"
        ixz="3.50583392437512E-06"
        iyy="0.00011462399449212"
        iyz="-1.95086999820293E-08"
        izz="0.000157908884644634" />
    </inertial>
    <visual>
      <origin
        xyz="0 0 0"
        rpy="0 0 0" />
      <geometry>
        <mesh
          filename="package://arm_description/meshes/link_5.STL" />
      </geometry>
      <material
        name="">
        <color
          rgba="0.752941176470588 0.752941176470588 0.752941176470588 1" />
      </material>
    </visual>
    <collision>
      <origin
        xyz="0 0 0"
        rpy="0 0 0" />
      <geometry>
        <mesh
          filename="package://arm_description/meshes/link_5.STL" />
      </geometry>
    </collision>
  </link>
  <joint
    name="joint_5"
    type="revolute">
    <origin
      xyz="0 0 0.0909852058624292"
      rpy="1.5707963267949 1.5707963267949 0" />
    <parent
      link="link_4" />
    <child
      link="link_5" />
    <axis
      xyz="0 0 1" />
    <limit
      lower="-3.14"
      upper="3.14"
      effort="200"
      velocity="10" />
  </joint>
  <link
    name="link_6">
    <inertial>
      <origin
        xyz="4.1108599771425E-05 0.00257530402715245 0.0857796541219091"
        rpy="0 0 0" />
      <mass
        value="0.145620756588228" />
      <inertia
        ixx="9.17894079115679E-05"
        ixy="-9.76230646695244E-09"
        ixz="-3.67352230545461E-08"
        iyy="9.06990729876771E-05"
        iyz="3.51811623142638E-06"
        izz="0.000140766609119444" />
    </inertial>
    <visual>
      <origin
        xyz="0 0 0"
        rpy="0 0 0" />
      <geometry>
        <mesh
          filename="package://arm_description/meshes/link_6.STL" />
      </geometry>
      <material
        name="">
        <color
          rgba="0.752941176470588 0.752941176470588 0.752941176470588 1" />
      </material>
    </visual>
    <collision>
      <origin
        xyz="0 0 0"
        rpy="0 0 0" />
      <geometry>
        <mesh
          filename="package://arm_description/meshes/link_6.STL" />
      </geometry>
    </collision>
  </link>
  <joint
    name="joint_6"
    type="revolute">
    <origin
      xyz="0 0 0.19698520586243"
      rpy="1.5707963267949 0 1.5707963267949" />
    <parent
      link="link_5" />
    <child
      link="link_6" />
    <axis
      xyz="0 0 1" />
    <limit
      lower="-2.09"
      upper="2.09"
      effort="200"
      velocity="10" />
  </joint>
  <link
    name="link_7">
    <inertial>
      <origin
        xyz="3.04281750937718E-05 0.00389253372731124 -0.0873287224716446"
        rpy="0 0 0" />
      <mass
        value="0.208798877978331" />
      <inertia
        ixx="0.000104218009947256"
        ixy="1.7457482471701E-08"
        ixz="5.38289410367352E-08"
        iyy="0.000112327075315552"
        iyz="3.51730775061429E-06"
        izz="0.00015338924637272" />
    </inertial>
    <visual>
      <origin
        xyz="0 0 0"
        rpy="0 0 0" />
      <geometry>
        <mesh
          filename="package://arm_description/meshes/link_7.STL" />
      </geometry>
      <material
        name="">
        <color
          rgba="0.752941176470588 0.752941176470588 0.752941176470588 1" />
      </material>
    </visual>
    <collision>
      <origin
        xyz="0 0 0"
        rpy="0 0 0" />
      <geometry>
        <mesh
          filename="package://arm_description/meshes/link_7.STL" />
      </geometry>
    </collision>
  </link>
  <joint
    name="joint_7"
    type="revolute">
    <origin
      xyz="0 0 0.0909852058624294"
      rpy="1.5707963267949 -1.5707963267949 0" />
    <parent
      link="link_6" />
    <child
      link="link_7" />
    <axis
      xyz="0 0 -1" />
    <limit
      lower="-3.14"
      upper="3.14"
      effort="200"
      velocity="10" />
  </joint>
  <link
    name="tool_link">
    <inertial>
      <origin
        xyz="7.36277588972434E-06 9.79545500175982E-05 0.0224262437077161"
        rpy="0 0 0" />
      <mass
        value="0.125010719073419" />
      <inertia
        ixx="2.2629392203171E-05"
        ixy="2.32911033544108E-06"
        ixz="8.59002610735225E-10"
        iyy="0.00012815635241114"
        iyz="5.55851104808758E-09"
        izz="0.000144851958518917" />
    </inertial>
    <visual>
      <origin
        xyz="0 0 0"
        rpy="0 0 0" />
      <geometry>
        <mesh
          filename="package://arm_description/meshes/tool_link.STL" />
      </geometry>
      <material
        name="">
        <color
          rgba="0.250980392156863 0.250980392156863 0.250980392156863 1" />
      </material>
    </visual>
    <collision>
      <origin
        xyz="0 0 0"
        rpy="0 0 0" />
      <geometry>
        <mesh
          filename="package://arm_description/meshes/tool_link.STL" />
      </geometry>
    </collision>
  </link>
  <joint
    name="tool_joint"
    type="revolute">
    <origin
      xyz="0 -0.106485205862441 -0.0909852058624315"
      rpy="-1.5707963267949 0 0" />
    <parent
      link="link_7" />
    <child
      link="tool_link" />
    <axis
      xyz="0 0 -1" />
    <limit
      lower="-3.14"
      upper="3.14"
      effort="200"
      velocity="5" />
  </joint>
  <link
    name="grip_left_link">
    <inertial>
      <origin
        xyz="-0.0472057386689509 -0.00225339802100599 0.00189665039114234"
        rpy="0 0 0" />
      <mass
        value="0.0199960953484895" />
      <inertia
        ixx="6.8520261009693E-06"
        ixy="6.28134392390056E-07"
        ixz="-1.03874099356176E-06"
        iyy="6.67336841270338E-06"
        iyz="8.79996273613866E-07"
        izz="5.95029100616287E-06" />
    </inertial>
    <visual>
      <origin
        xyz="0 0 0"
        rpy="0 0 0" />
      <geometry>
        <mesh
          filename="package://arm_description/meshes/grip_left_link.STL" />
      </geometry>
      <material
        name="">
        <color
          rgba="1 1 1 1" />
      </material>
    </visual>
    <collision>
      <origin
        xyz="0 0 0"
        rpy="0 0 0" />
      <geometry>
        <mesh
          filename="package://arm_description/meshes/grip_left_link.STL" />
      </geometry>
    </collision>
  </link>
  <joint
    name="grip_left_joint"
    type="prismatic">
    <origin
      xyz="0 0 -0.0135"
      rpy="0 0 0" />
    <parent
      link="tool_link" />
    <child
      link="grip_left_link" />
    <axis
      xyz="-1 0 0" />
    <limit
      lower="-0.04"
      upper="0"
      effort="1"
      velocity="5" />
  </joint>
  <link
    name="grip_right_link">
    <inertial>
      <origin
        xyz="0.0436880923241129 0.0022533980210061 0.00189665039114277"
        rpy="0 0 0" />
      <mass
        value="0.0199960953484896" />
      <inertia
        ixx="6.85202610096932E-06"
        ixy="6.28134392390057E-07"
        ixz="1.03874099356176E-06"
        iyy="6.67336841270338E-06"
        iyz="-8.7999627361387E-07"
        izz="5.95029100616288E-06" />
    </inertial>
    <visual>
      <origin
        xyz="0 0 0"
        rpy="0 0 0" />
      <geometry>
        <mesh
          filename="package://arm_description/meshes/grip_right_link.STL" />
      </geometry>
      <material
        name="">
        <color
          rgba="1 1 1 1" />
      </material>
    </visual>
    <collision>
      <origin
        xyz="0 0 0"
        rpy="0 0 0" />
      <geometry>
        <mesh
          filename="package://arm_description/meshes/grip_right_link.STL" />
      </geometry>
    </collision>
  </link>
  <joint
    name="grip_right_joint"
    type="prismatic">
    <origin
      xyz="0 0 -0.0135"
      rpy="0 0 0" />
    <parent
      link="tool_link" />
    <child
      link="grip_right_link" />
    <axis
      xyz="-1 0 0" />
    <limit
      lower="0"
      upper="0.04"
      effort="1"
      velocity="5" />
  </joint>
  <link
    name="cam_link">
    <inertial>
      <origin
        xyz="0.00500000001588299 0.0402001871503386 0.0453894603646021"
        rpy="0 0 0" />
      <mass
        value="0.0659679326018229" />
      <inertia
        ixx="9.59737991069113E-06"
        ixy="-1.16335497990539E-13"
        ixz="-4.4922770867215E-16"
        iyy="3.38968989688438E-05"
        iyz="3.22132929115363E-08"
        izz="3.60134968230216E-05" />
    </inertial>
    <visual>
      <origin
        xyz="0 0 0"
        rpy="0 0 0" />
      <geometry>
        <mesh
          filename="package://arm_description/meshes/cam_link.STL" />
      </geometry>
      <material
        name="">
        <color
          rgba="0.250980392156863 0.250980392156863 0.250980392156863 1" />
      </material>
    </visual>
    <collision>
      <origin
        xyz="0 0 0"
        rpy="0 0 0" />
      <geometry>
        <mesh
          filename="package://arm_description/meshes/cam_link.STL" />
      </geometry>
    </collision>
  </link>
  <joint
    name="cam_joint"
    type="fixed">
    <origin
      xyz="0 0 -0.0135"
      rpy="0 0 0" />
    <parent
      link="tool_link" />
    <child
      link="cam_link" />
    <axis
      xyz="0 0 0" />
  </joint>
</robot>