<?xml version="1.0" encoding="utf-8"?>
<!-- This URDF was automatically created by SolidWorks to URDF Exporter! Originally created by Stephen Brawner (brawner@gmail.com) 
     Commit Version: 1.6.0-4-g7f85cfe  Build Version: 1.6.7995.38578
     For more information, please see http://wiki.ros.org/sw_urdf_exporter -->
<robot name="arm_description">
  <link name="world" />
  <joint name="world_to_base" type="fixed">
    <parent link="world" />
    <child link="base_link" />
    <origin xyz="0 0 0" rpy="0 0 0" />
  </joint>
  <link name="base_link">
    <inertial>
      <origin xyz="-2.08175701580243E-05 -0.0215944619940899 0.0386965059587762" rpy="0 0 0" />
      <mass value="0.226867575584474" />
      <inertia ixx="0.000310138970163127" ixy="3.57652047089324E-08" ixz="2.76570159637442E-09" iyy="0.000172445953154283" iyz="-1.18759040248718E-05" izz="0.000403590658467127" />
    </inertial>
    <visual>
      <origin xyz="0 0 0" rpy="0 0 0" />
      <geometry>
        <mesh filename="package://arm_description/meshes/base_link.STL" />
      </geometry>
      <material name="">
        <color rgba="0.752941176470588 0.752941176470588 0.752941176470588 1" />
      </material>
    </visual>
    <collision>
      <origin xyz="0 0 0" rpy="0 0 0" />
      <geometry>
        <mesh filename="package://arm_description/meshes/base_link.STL" />
      </geometry>
    </collision>
  </link>
  <link name="link_1">
    <inertial>
      <origin xyz="0.00362239334791756 -3.81795642908633E-05 0.140982620125569" rpy="0 0 0" />
      <mass value="0.141639977131661" />
      <inertia ixx="8.98141382308835E-05" ixy="1.13468736177962E-08" ixz="3.51673525250542E-06" iyy="9.15722320805618E-05" iyz="3.6542592292488E-08" izz="0.000140053948831358" />
    </inertial>
    <visual>
      <origin xyz="0 0 0" rpy="0 0 0" />
      <geometry>
        <mesh filename="package://arm_description/meshes/link_1.STL" />
      </geometry>
      <material name="">
        <color rgba="0.752941176470588 0.752941176470588 0.752941176470588 1" />
      </material>
    </visual>
    <collision>
      <origin xyz="0 0 0" rpy="0 0 0" />
      <geometry>
        <mesh filename="package://arm_description/meshes/link_1.STL" />
      </geometry>
    </collision>
  </link>
  <joint name="joint_1" type="revolute">
    <origin xyz="0 0 0" rpy="0 0 0" />
    <parent link="base_link" />
    <child link="link_1" />
    <axis xyz="0 0 1" />
    <limit lower="-0.785398" upper="3.92699" effort="2" velocity="3" />
  </joint>
  <link name="link_2">
    <inertial>
      <origin xyz="7.53940182482427E-06 0.00505678180282546 0.0842129380713663" rpy="0 0 0" />
      <mass value="0.143507549223786" />
      <inertia ixx="9.77478537604331E-05" ixy="-1.67427633619241E-08" ixz="-1.8083438756804E-08" iyy="9.07459548934155E-05" iyz="3.57849204977034E-06" izz="0.000147113534917112" />
    </inertial>
    <visual>
      <origin xyz="0 0 0" rpy="0 0 0" />
      <geometry>
        <mesh filename="package://arm_description/meshes/link_2.STL" />
      </geometry>
      <material name="">
        <color rgba="0.752941176470588 0.752941176470588 0.752941176470588 1" />
      </material>
    </visual>
    <collision>
      <origin xyz="0 0 0" rpy="0 0 0" />
      <geometry>
        <mesh filename="package://arm_description/meshes/link_2.STL" />
      </geometry>
    </collision>
  </link>
  <joint name="joint_2" type="revolute">
    <origin xyz="0 0 0.1464" rpy="1.5707963267949 0 1.5707963267949" />
    <parent link="link_1" />
    <child link="link_2" />
    <axis xyz="0 0 1" />
    <limit lower="-1.57" upper="1.57" effort="2" velocity="3" />
  </joint>
  <link name="link_3">
    <inertial>
      <origin xyz="-0.00330775018246701 -1.51931359661378E-05 -0.215292675404989" rpy="0 0 0" />
      <mass value="0.173954075434222" />
      <inertia ixx="0.000144630940442922" ixy="-1.32847181187994E-07" ixz="3.53526021477459E-06" iyy="0.000147338139082199" iyz="-6.41277682295082E-09" izz="0.000161646518516295" />
    </inertial>
    <visual>
      <origin xyz="0 0 0" rpy="0 0 0" />
      <geometry>
        <mesh filename="package://arm_description/meshes/link_3.STL" />
      </geometry>
      <material name="">
        <color rgba="0.752941176470588 0.752941176470588 0.752941176470588 1" />
      </material>
    </visual>
    <collision>
      <origin xyz="0 0 0" rpy="0 0 0" />
      <geometry>
        <mesh filename="package://arm_description/meshes/link_3.STL" />
      </geometry>
    </collision>
  </link>
  <joint name="joint_3" type="revolute">
    <origin xyz="0 0 0.0894999999999936" rpy="1.5707963267949 -1.5707963267949 0" />
    <parent link="link_2" />
    <child link="link_3" />
    <axis xyz="0 0 -1" />
    <limit lower="-3.14" upper="3.14" effort="2" velocity="3" />
  </joint>
  <link name="link_4">
    <inertial>
      <origin xyz="-3.69732387454358E-05 -0.0033965928719577 0.0858843482112302" rpy="0 0 0" />
      <mass value="0.148325167434625" />
      <inertia ixx="9.83824919124809E-05" ixy="-8.95348942306975E-09" ixz="3.53186062441229E-08" iyy="9.2436601034005E-05" iyz="-3.58230406317328E-06" izz="0.000148216123686448" />
    </inertial>
    <visual>
      <origin xyz="0 0 0" rpy="0 0 0" />
      <geometry>
        <mesh filename="package://arm_description/meshes/link_4.STL" />
      </geometry>
      <material name="">
        <color rgba="0.752941176470588 0.752941176470588 0.752941176470588 1" />
      </material>
    </visual>
    <collision>
      <origin xyz="0 0 0" rpy="0 0 0" />
      <geometry>
        <mesh filename="package://arm_description/meshes/link_4.STL" />
      </geometry>
    </collision>
  </link>
  <joint name="joint_4" type="revolute">
    <origin xyz="0 0 -0.24698520586243" rpy="1.5707963267949 0 -1.5707963267949" />
    <parent link="link_3" />
    <child link="link_4" />
    <axis xyz="0 0 1" />
    <limit lower="-2.09" upper="2.09" effort="2" velocity="3" />
  </joint>
  <link name="link_5">
    <inertial>
      <origin xyz="0.00206792792814742 -2.76614863313485E-05 0.175346578298024" rpy="0 0 0" />
      <mass value="0.170949127914978" />
      <inertia ixx="0.000112877897565311" ixy="1.33876282485736E-07" ixz="3.50583392437512E-06" iyy="0.00011462399449212" iyz="-1.95086999820314E-08" izz="0.000157908884644634" />
    </inertial>
    <visual>
      <origin xyz="0 0 0" rpy="0 0 0" />
      <geometry>
        <mesh filename="package://arm_description/meshes/link_5.STL" />
      </geometry>
      <material name="">
        <color rgba="0.752941176470588 0.752941176470588 0.752941176470588 1" />
      </material>
    </visual>
    <collision>
      <origin xyz="0 0 0" rpy="0 0 0" />
      <geometry>
        <mesh filename="package://arm_description/meshes/link_5.STL" />
      </geometry>
    </collision>
  </link>
  <joint name="joint_5" type="revolute">
    <origin xyz="0 0 0.0909852058624292" rpy="1.5707963267949 1.5707963267949 0" />
    <parent link="link_4" />
    <child link="link_5" />
    <axis xyz="0 0 1" />
    <limit lower="-3.14" upper="3.14" effort="2" velocity="3" />
  </joint>
  <link name="link_6">
    <inertial>
      <origin xyz="4.11085997713834E-05 0.00257530402715256 0.0857796541219091" rpy="0 0 0" />
      <mass value="0.145620756588228" />
      <inertia ixx="9.17894079115679E-05" ixy="-9.76230646695324E-09" ixz="-3.67352230545471E-08" iyy="9.06990729876771E-05" iyz="3.51811623142639E-06" izz="0.000140766609119444" />
    </inertial>
    <visual>
      <origin xyz="0 0 0" rpy="0 0 0" />
      <geometry>
        <mesh filename="package://arm_description/meshes/link_6.STL" />
      </geometry>
      <material name="">
        <color rgba="0.752941176470588 0.752941176470588 0.752941176470588 1" />
      </material>
    </visual>
    <collision>
      <origin xyz="0 0 0" rpy="0 0 0" />
      <geometry>
        <mesh filename="package://arm_description/meshes/link_6.STL" />
      </geometry>
    </collision>
  </link>
  <joint name="joint_6" type="revolute">
    <origin xyz="0 0 0.19698520586243" rpy="1.5707963267949 0 1.5707963267949" />
    <parent link="link_5" />
    <child link="link_6" />
    <axis xyz="0 0 1" />
    <limit lower="-2.09" upper="2.09" effort="2" velocity="3" />
  </joint>
  <link name="link_7">
    <inertial>
      <origin xyz="3.04281750932445E-05 0.00389253372731124 -0.0873287224716447" rpy="0 0 0" />
      <mass value="0.208798877978331" />
      <inertia ixx="0.000104218009947256" ixy="1.74574824717128E-08" ixz="5.38289410367358E-08" iyy="0.000112327075315552" iyz="3.51730775061429E-06" izz="0.00015338924637272" />
    </inertial>
    <visual>
      <origin xyz="0 0 0" rpy="0 0 0" />
      <geometry>
        <mesh filename="package://arm_description/meshes/link_7.STL" />
      </geometry>
      <material name="">
        <color rgba="0.752941176470588 0.752941176470588 0.752941176470588 1" />
      </material>
    </visual>
    <collision>
      <origin xyz="0 0 0" rpy="0 0 0" />
      <geometry>
        <mesh filename="package://arm_description/meshes/link_7.STL" />
      </geometry>
    </collision>
  </link>
  <joint name="joint_7" type="revolute">
    <origin xyz="0 0 0.0909852058624294" rpy="1.5707963267949 -1.5707963267949 0" />
    <parent link="link_6" />
    <child link="link_7" />
    <axis xyz="0 0 -1" />
    <limit lower="-2.09" upper="2.09" effort="2" velocity="3" />
  </joint>
  <link name="tool_frame">
    <inertial>
      <origin xyz="2.64411535884357E-05 9.79545500181533E-05 0.0184262437077161" rpy="0 0 0" />
      <mass value="0.125010719073419" />
      <inertia ixx="2.2629392203171E-05" ixy="2.32911033544108E-06" ixz="8.5900261072939E-10" iyy="0.00012815635241114" iyz="5.55851104809067E-09" izz="0.000144851958518917" />
    </inertial>
    <visual>
      <origin xyz="0 0 0" rpy="0 0 0" />
      <geometry>
        <mesh filename="package://arm_description/meshes/tool_frame.STL" />
      </geometry>
      <material name="">
        <color rgba="0.250980392156863 0.250980392156863 0.250980392156863 1" />
      </material>
    </visual>
    <collision>
      <origin xyz="0 0 0" rpy="0 0 0" />
      <geometry>
        <mesh filename="package://arm_description/meshes/tool_frame.STL" />
      </geometry>
    </collision>
  </link>
  <joint name="tool_joint" type="revolute">
    <origin xyz="0 -0.102485205862441 -0.0909852058624315" rpy="-1.5707963267949 0 0" />
    <parent link="link_7" />
    <child link="tool_frame" />
    <axis xyz="0 0 -1" />
    <limit lower="-2.09" upper="2.09" effort="2" velocity="3" />
  </joint>
  <link name="grip_left">
    <inertial>
      <origin xyz="-0.0454469154965145 -0.00225339802100599 -0.0156033496088577" rpy="0 0 0" />
      <mass value="0.0199960953484895" />
      <inertia ixx="6.8520261009693E-06" ixy="6.28134392390056E-07" ixz="-1.03874099356176E-06" iyy="6.67336841270338E-06" iyz="8.79996273613866E-07" izz="5.95029100616287E-06" />
    </inertial>
    <visual>
      <origin xyz="0 0 0" rpy="0 0 0" />
      <geometry>
        <mesh filename="package://arm_description/meshes/grip_left.STL" />
      </geometry>
      <material name="">
        <color rgba="0.792156862745098 0.819607843137255 0.933333333333333 1" />
      </material>
    </visual>
    <collision>
      <origin xyz="0 0 0" rpy="0 0 0" />
      <geometry>
        <mesh filename="package://arm_description/meshes/grip_left.STL" />
      </geometry>
    </collision>
  </link>
  <joint name="grip_left" type="prismatic">
    <origin xyz="0 0 0" rpy="0 0 0" />
    <parent link="tool_frame" />
    <child link="grip_left" />
    <axis xyz="-1 0 0" />
    <limit lower="-0.04" upper="0" effort="1" velocity="0.5" />
  </joint>
  <link name="grip_right">
    <inertial>
      <origin xyz="0.0454469154965374 0.00225339802100588 -0.0156033496088577" rpy="0 0 0" />
      <mass value="0.0199960953484896" />
      <inertia ixx="6.85202610096932E-06" ixy="6.28134392390057E-07" ixz="1.03874099356176E-06" iyy="6.67336841270338E-06" iyz="-8.7999627361387E-07" izz="5.95029100616287E-06" />
    </inertial>
    <visual>
      <origin xyz="0 0 0" rpy="0 0 0" />
      <geometry>
        <mesh filename="package://arm_description/meshes/grip_right.STL" />
      </geometry>
      <material name="">
        <color rgba="0.792156862745098 0.819607843137255 0.933333333333333 1" />
      </material>
    </visual>
    <collision>
      <origin xyz="0 0 0" rpy="0 0 0" />
      <geometry>
        <mesh filename="package://arm_description/meshes/grip_right.STL" />
      </geometry>
    </collision>
  </link>
  <joint name="grip_right" type="prismatic">
    <origin xyz="0 0 0" rpy="0 0 0" />
    <parent link="tool_frame" />
    <child link="grip_right" />
    <axis xyz="-1 0 0" />
    <limit lower="0" upper="0.04" effort="1" velocity="0.5" />
  </joint>
</robot>